Workbook

Sheet set 1234
A1: I5_Index_ID | B1: index2 | D1: I5 RC· | F1: I7_Index_ID | G1: index
A2: D501 | B2: AGGCTATA | D2: TATAGCCT | F2: D701 | G2: ATTACTCG | I2: 1 | J2: =A2&"-"&F2 | K2: =D2&""&G2 | Q2: 325
A3: D501 | B3: AGGCTATA | D3: TATAGCCT | F3: D702 | G3: TCCGGAGA | I3: 2 | J3: =A3&"-"&F3 | K3: =D3&""&G3 | Q3: 326
A4: D501 | B4: AGGCTATA | D4: TATAGCCT | F4: D703 | G4: CGCTCATT | I4: 3 | J4: =A4&"-"&F4 | K4: =D4&""&G4 | Q4: 327
A5: D501 | B5: AGGCTATA | D5: TATAGCCT | F5: D704 | G5: GAGATTCC | I5: 4 | J5: =A5&"-"&F5 | K5: =D5&""&G5 | Q5: 328
A6: D502 | B6: GCCTCTAT | D6: ATAGAGGC | F6: D701 | G6: ATTACTCG | I6: 5 | J6: =A6&"-"&F6 | K6: =D6&""&G6 | Q6: 329
A7: D502 | B7: GCCTCTAT | D7: ATAGAGGC | F7: D702 | G7: TCCGGAGA | I7: 6 | J7: =A7&"-"&F7 | K7: =D7&""&G7 | Q7: 330
A8: D502 | B8: GCCTCTAT | D8: ATAGAGGC | F8: D703 | G8: CGCTCATT | I8: 7 | J8: =A8&"-"&F8 | K8: =D8&""&G8 | Q8: 331
A9: D502 | B9: GCCTCTAT | D9: ATAGAGGC | F9: D704 | G9: GAGATTCC | I9: 8 | J9: =A9&"-"&F9 | K9: =D9&""&G9 | Q9: 332
A10: D503 | B10: AGGATAGG | D10: CCTATCCT | F10: D701 | G10: ATTACTCG | I10: 9 | J10: =A10&"-"&F10 | K10: =D10&""&G10 | Q10: 333
A11: D503 | B11: AGGATAGG | D11: CCTATCCT | F11: D702 | G11: TCCGGAGA | I11: 10 | J11: =A11&"-"&F11 | K11: =D11&""&G11 | Q11: 334
A12: D503 | B12: AGGATAGG | D12: CCTATCCT | F12: D703 | G12: CGCTCATT | I12: 11 | J12: =A12&"-"&F12 | K12: =D12&""&G12 | Q12: 335
A13: D503 | B13: AGGATAGG | D13: CCTATCCT | F13: D704 | G13: GAGATTCC | I13: 12 | J13: =A13&"-"&F13 | K13: =D13&""&G13 | Q13: 336
... A157: D515 | B157: ATGCCACA | D157: TGTGGCAT | F157: D720 | G157: AAGCGTTC | I157: 156 | J157: =A157&"-"&F157 | K157: =D157&""&G157 | Q157: 260
A158: D516 | B158: TCCGTAGT | D158: ACTACGGA | F158: D717 | G158: GGATCTGA | I158: 157 | J158: =A158&"-"&F158 | K158: =D158&""&G158
A159: D516 | B159: TCCGTAGT | D159: ACTACGGA | F159: D718 | G159: TGATCACG | I159: 158 | J159: =A159&"-"&F159 | K159: =D159&""&G159
A160: D516 | B160: TCCGTAGT | D160: ACTACGGA | F160: D719 | G160: AAGCGACT | I160: 159 | J160: =A160&"-"&F160 | K160: =D160&""&G160
A161: D516 | B161: TCCGTAGT | D161: ACTACGGA | F161: D720 | G161: AAGCGTTC | I161: 160 | J161: =A161&"-"&F161 | K161: =D161&""&G161
A162: D509 | B162: GCAAGCAA | D162: TTGCTTGC | F162: D721 | G162: AAGGCGTA | I162: 161 | J162: =A162&"-"&F162 | K162: =D162&""&G162
A163: D509 | B163: GCAAGCAA | D163: TTGCTTGC | F163: D722 | G163: CTGATGAG | I163: 162 | J163: =A163&"-"&F163 | K163: =D163&""&G163
A164: D509 | B164: GCAAGCAA | D164: TTGCTTGC | F164: D723 | G164: GCAGAAGA | I164: 163 | J164: =A164&"-"&F164 | K164: =D164&""&G164
A165: D509 | B165: GCAAGCAA | D165: TTGCTTGC | F165: D724 | G165: AATCCAGC | I165: 164 | J165: =A165&"-"&F165 | K165: =D165&""&G165
A166: D510 | B166: AACCTCTC | D166: GAGAGGTT | F166: D721 | G166: AAGGCGTA | I166: 165 | J166: =A166&"-"&F166 | K166: =D166&""&G166
A167: D510 | B167: AACCTCTC | D167: GAGAGGTT | F167: D722 | G167: CTGATGAG | I167: 166 | J167: =A167&"-"&F167 | K167: =D167&""&G167
A168: D510 | B168: AACCTCTC | D168: GAGAGGTT | F168: D723 | G168: GCAGAAGA | I168: 167 | J168: =A168&"-"&F168 | K168: =D168&""&G168
A169: D510 | B169: AACCTCTC | D169: GAGAGGTT | F169: D724 | G169: AATCCAGC | I169: 168 | J169: =A169&"-"&F169 | K169: =D169&""&G169
... A385: D516 | B385: TCCGTAGT | D385: ACTACGGA | F385: D712 | G385: AGCGATAG | I385: 384 | J385: =A385&"-"&F385 | K385: =D385&""&G385

Sheet Set 5678
B1: i5 | D1: i5RC | G1: i7 | J1: Primer | K1: ID | L1: Sequence
A2: S5501 | B2: CGTATTCG | D2: CGAATACG | F2: S5701 | G2: TTACCGAC | J2: 385 | K2: =A2&"-"&F2 | L2: =D2&""&G2
A3: S5502 | B3: TCAAGGAC | D3: GTCCTTGA | F3: S5702 | G3: TCGTCTGA | J3: 386 | K3: =A3&"-"&F3 | L3: =D3&""&G3
A4: S5503 | B4: AAGCACTG | D4: CAGTGCTT | F4: S5703 | G4: TTCCAGGT | J4: 387 | K4: =A4&"-"&F4 | L4: =D4&""&G4
A5: S5504 | B5: GCAATGGA | D5: TCCATTGC | F5: S5704 | G5: TACGGTCT | J5: 388 | K5: =A5&"-"&F5 | L5: =D5&""&G5
A6: S5505 | B6: CAATCGAC | D6: GTCGATTG | F6: S5705 | G6: AAGACCGT | J6: 389 | K6: =A6&"-"&F6 | L6: =D6&""&G6
A7: S5506 | B7: GGCGTTAT | D7: ATAACGCC | F7: S5706 | G7: CAGGTTCA | J7: 390 | K7: =A7&"-"&F7 | L7: =D7&""&G7
A8: S5507 | B8: GTTAAGGC | D8: GCCTTAAC | F8: S5707 | G8: TAGGAGCT | J8: 391 | K8: =A8&"-"&F8 | L8: =D8&""&G8
A9: S5508 | B9: CCTATACC | D9: GGTATAGG | F9: S5708 | G9: TACTCCAG | J9: 392 | K9: =A9&"-"&F9 | L9: =D9&""&G9
A10: S5509 | B10: CTCCTAGA | D10: TCTAGGAG | F10: S5709 | G10: AGTGACCT | J10: 393 | K10: =A10&"-"&F10 | L10: =D10&""&G10
A11: S5510 | B11: GTTACGCA | D11: TGCGTAAC | F11: S5710 | G11: AGCCTATC | J11: 394 | K11: =A11&"-"&F11 | L11: =D11&""&G11
A12: S5511 | B12: CTAGCAAG | D12: CTTGCTAG | F12: S5711 | G12: TCATCTCC | J12: 395 | K12: =A12&"-"&F12 | L12: =D12&""&G12
A13: S5512 | B13: ATCTCGCT | D13: AGCGAGAT | F13: S5712 | G13: CCAGTATC | J13: 396 | K13: =A13&"-"&F13 | L13: =D13&""&G13
... A97: S5596 | B97: TGTGGTAC | D97: GTACCACA | F97: S5796 | G97: CCACAACA | J97: 480 | K97: =A97&"-"&F97 | L97: =D97&""&G97
K98: =A98&"-"&F98 | L98: =D98&""&G98
A99: S6501 | B99: AGTCGCTT | D99: AAGCGACT | F99: S6701 | G99: CACTGTAG | J99: 481 | K99: =A99&"-"&F99 | L99: =D99&""&G99
A100: S6502 | B100: GCCTATCA | D100: TGATAGGC | F100: S6702 | G100: GTGCACGA | J100: 482 | K100: =A100&"-"&F100 | L100: =D100&""&G100
A101: S6503 | B101: GGCGCTGA | D101: TCAGCGCC | F101: S6703 | G101: ATGTTCCT | J101: 483 | K101: =A101&"-"&F101 | L101: =D101&""&G101
A102: S6504 | B102: ATGTGACT | D102: AGTCACAT | F102: S6704 | G102: CATTATGG | J102: 484 | K102: =A102&"-"&F102 | L102: =D102&""&G102
A103: S6505 | B103: GTGAAAGG | D103: CCTTTCAC | F103: S6705 | G103: TCTTGTTT | J103: 485 | K103: =A103&"-"&F103 | L103: =D103&""&G103
A104: S6506 | B104: AGGGAAAG | D104: CTTTCCCT | F104: S6706 | G104: GGCTTACT | J104: 486 | K104: =A104&"-"&F104 | L104: =D104&""&G104
A105: S6507 | B105: GAATTGTC | D105: GACAATTC | F105: S6707 | G105: ACGATATG | J105: 487 | K105: =A105&"-"&F105 | L105: =D105&""&G105
A106: S6508 | B106: AGTCGTGT | D106: ACACGACT | F106: S6708 | G106: ATCCGCAG | J106: 488 | K106: =A106&"-"&F106 | L106: =D106&""&G106
A107: S6509 | B107: GGATTCGT | D107: ACGAATCC | F107: S6709 | G107: AAGCGACT | J107: 489 | K107: =A107&"-"&F107 | L107: =D107&""&G107
A108: S6510 | B108: ACTCAGAC | D108: GTCTGAGT | F108: S6710 | G108: TGATAGGC | J108: 490 | K108: =A108&"-"&F108 | L108: =D108&""&G108
A109: S6511 | B109: CTCACACC | D109: GGTGTGAG | F109: S6711 | G109: AACACCAC | J109: 491 | K109: =A109&"-"&F109 | L109: =D109&""&G109
A110: S6512 | B110: TATGCAAG | D110: CTTGCATA | F110: S6712 | G110: ACCTCTTC | J110: 492 | K110: =A110&"-"&F110 | L110: =D110&""&G110
... A194: S6596 | B194: CTCGGTTG | D194: CAACCGAG | F194: S6796 | G194: TACCTGTG | J194: 576 | K194: =A194&"-"&F194 | L194: =D194&""&G194
K195: =A195&"-"&F195 | L195: =D195&""&G195
A196: S7501 | B196: TTAGCTTT | D196: AAAGCTAA | F196: S7701 | G196: TGTCGTAG | J196: 577 | K196: =A196&"-"&F196 | L196: =D196&""&G196 | N196: 577
A197: S7502 | B197: AATCTCCA | D197: TGGAGATT | F197: S7702 | G197: CAATCATA | J197: 578 | K197: =A197&"-"&F197 | L197: =D197&""&G197 | N197: 578
A198: S7503 | B198: GTCTAATT | D198: AATTAGAC | F198: S7703 | G198: GTTCTTAT | J198: 579 | K198: =A198&"-"&F198 | L198: =D198&""&G198 | N198: 579
A199: S7504 | B199: CCCAAAGT | D199: ACTTTGGG | F199: S7704 | G199: GATGCGAC | J199: 580 | K199: =A199&"-"&F199 | L199: =D199&""&G199 | N199: 580
A200: S7505 | B200: TCCGTCCG | D200: CGGACGGA | F200: S7705 | G200: GAAGAGGG | J200: 581 | K200: =A200&"-"&F200 | L200: =D200&""&G200 | N200: 581
A201: S7506 | B201: GGCTCTGC | D201: GCAGAGCC | F201: S7706 | G201: TAGTAATC | J201: 582 | K201: =A201&"-"&F201 | L201: =D201&""&G201 | N201: 582
A202: S7507 | B202: GATCATGC | D202: GCATGATC | F202: S7707 | G202: GTGTGGAG | J202: 583 | K202: =A202&"-"&F202 | L202: =D202&""&G202 | N202: 583
A203: S7508 | B203: TAGGTCGA | D203: TCGACCTA | F203: S7708 | G203: ACGTTGTA | J203: 584 | K203: =A203&"-"&F203 | L203: =D203&""&G203 | N203: 584
A204: S7509 | B204: GTCAGGGT | D204: ACCCTGAC | F204: S7709 | G204: GCGCTAAT | J204: 585 | K204: =A204&"-"&F204 | L204: =D204&""&G204 | N204: 601
A205: S7510 | B205: CCTTCAAC | D205: GTTGAAGG | F205: S7710 | G205: AGAGCTGC | J205: 586 | K205: =A205&"-"&F205 | L205: =D205&""&G205 | N205: 602
A206: S7511 | B206: TCCCGTGC | D206: GCACGGGA | F206: S7711 | G206: CATACTTA | J206: 587 | K206: =A206&"-"&F206 | L206: =D206&""&G206 | N206: 603
...

Sheet set 9
B1: i5 | D1: i5rc | G1: i7 | M1: S95001-S97001 | N1: ATATGCGCCTGATCGT
A2: S95001 | B2: GCGCATAT | D2: ATATGCGC | F2: S97001 | G2: CTGATCGT | I2: 769 | J2: =A2&"-"&F2 | K2: =D2&""&G2 | M2: S95002-S97002 | N2: TGGTACAGACTCTCGA
A3: S95002 | B3: CTGTACCA | D3: TGGTACAG | F3: S97002 | G3: ACTCTCGA | I3: 770 | J3: =A3&"-"&F3 | K3: =D3&""&G3 | M3: S95003-S97003 | N3: AACCGTTCTGAGCTAG
A4: S95003 | B4: GAACGGTT | D4: AACCGTTC | F4: S97003 | G4: TGAGCTAG | I4: 771 | J4: =A4&"-"&F4 | K4: =D4&""&G4 | M4: S95004-S97004 | N4: TAACCGGTGAGACGAT
A5: S95004 | B5: ACCGGTTA | D5: TAACCGGT | F5: S97004 | G5: GAGACGAT | I5: 772 | J5: =A5&"-"&F5 | K5: =D5&""&G5 | M5: S95005-S97005 | N5: GAACATCGCTTGTCGA
A6: S95005 | B6: CGATGTTC | D6: GAACATCG | F6: S97005 | G6: CTTGTCGA | I6: 773 | J6: =A6&"-"&F6 | K6: =D6&""&G6 | M6: S95006-S97006 | N6: CCTTGTAGTTCCAAGG
A7: S95006 | B7: CTACAAGG | D7: CCTTGTAG | F7: S97006 | G7: TTCCAAGG | I7: 774 | J7: =A7&"-"&F7 | K7: =D7&""&G7 | M7: S95007-S97007 | N7: TCAGGCTTCGCATGAT
A8: S95007 | B8: AAGCCTGA | D8: TCAGGCTT | F8: S97007 | G8: CGCATGAT | I8: 775 | J8: =A8&"-"&F8 | K8: =D8&""&G8 | M8: S95008-S97008 | N8: GTTCTCGTACGGAACA
A9: S95008 | B9: ACGAGAAC | D9: GTTCTCGT | F9: S97008 | G9: ACGGAACA | I9: 776 | J9: =A9&"-"&F9 | K9: =D9&""&G9 | M9: S95009-S97009 | N9: AGAACGAGCGGCTAAT
A10: S95009 | B10: CTCGTTCT | D10: AGAACGAG | F10: S97009 | G10: CGGCTAAT | I10: 777 | J10: =A10&"-"&F10 | K10: =D10&""&G10 | M10: S95010-S97010 | N10: TGCTTCCAATCGATCG
A11: S95010 | B11: TGGAAGCA | D11: TGCTTCCA | F11: S97010 | G11: ATCGATCG | I11: 778 | J11: =A11&"-"&F11 | K11: =D11&""&G11 | M11: S95011-S97011 | N11: CTTCGACTGCAAGATC
A12: S95011 | B12: AGTCGAAG | D12: CTTCGACT | F12: S97011 | G12: GCAAGATC | I12: 779 | J12: =A12&"-"&F12 | K12: =D12&""&G12 | M12: S95012-S97012 | N12: CACCTGTTGCTATCCT
A13: S95012 | B13: AACAGGTG | D13: CACCTGTT | F13: S97012 | G13: GCTATCCT | I13: 780 | J13: =A13&"-"&F13 | K13: =D13&""&G13 | M13: S95013-S97013 | N13: ATCACACGTACGCTAC
... A92: S95091 | B92: CCTTGGAA | D92: TTCCAAGG | F92: S97091 | G92: CCTTGTAG | I92: 859 | J92: =A92&"-"&F92 | K92: =D92&""&G92 | M92: S95096-S97096 | N92: CTGATCGTATATGCGC
A93: S95092 | B93: TCGACAAG | D93: CTTGTCGA | F93: S97092 | G93: GAACATCG | I93: 860 | J93: =A93&"-"&F93 | K93: =D93&""&G93
A94: S95093 | B94: ATCGTCTC | D94: GAGACGAT | F94: S97093 | G94: TAACCGGT | I94: 861 | J94: =A94&"-"&F94 | K94: =D94&""&G94
A95: S95094 | B95: CTAGCTCA | D95: TGAGCTAG | F95: S97094 | G95: AACCGTTC | I95: 862 | J95: =A95&"-"&F95 | K95: =D95&""&G95
A96: S95095 | B96: TCGAGAGT | D96: ACTCTCGA | F96: S97095 | G96: TGGTACAG | I96: 863 | J96: =A96&"-"&F96 | K96: =D96&""&G96
A97: S95096 | B97: ACGATCAG | D97: CTGATCGT | F97: S97096 | G97: ATATGCGC | I97: 864 | J97: =A97&"-"&F97 | K97: =D97&""&G97
K119: CGCATGATCACCTGTT
K120: CGCATGATCTTCGACT
K121: CGCATGATTGCTTCCA
K122: CGCATGATAGAACGAG
K123: TTCCAAGGCACCTGTT
K124: TTCCAAGGCTTCGACT
K125: TTCCAAGGTGCTTCCA
K126: TTCCAAGGAGAACGAG
K127: CTTGTCGACACCTGTT
K128: CTTGTCGACTTCGACT
K129: CTTGTCGATGCTTCCA
K130: CTTGTCGAAGAACGAG
... K194: CTGATCGTGAACATCG
K195: =D195&""&G195

Sheet Set 101112
B1: i5 | D1: i5 rc | G1: i7 | I1: Primer | J1: ID | K1: Sequence
A2: S95097 | B2: AATGGTCG | D2: CGACCATT | F2: S97097 | G2: GCCTATCA | I2: 865 | J2: =A2&"-"&F2 | K2: =D2&""&G2
A3: S95098 | B3: TCGCTATC | D3: GATAGCGA | F3: S97098 | G3: CTTGGATG | I3: 866 | J3: =A3&"-"&F3 | K3: =D3&""&G3
A4: S95099 | B4: CGTCCATT | D4: AATGGACG | F4: S97099 | G4: AGTCTCAC | I4: 867 | J4: =A4&"-"&F4 | K4: =D4&""&G4
A5: S95100 | B5: TACTAGCG | D5: CGCTAGTA | F5: S97100 | G5: CTCATCAG | I5: 868 | J5: =A5&"-"&F5 | K5: =D5&""&G5
A6: S95101 | B6: CCTAGAGA | D6: TCTCTAGG | F6: S97101 | G6: TGTACCGT | I6: 869 | J6: =A6&"-"&F6 | K6: =D6&""&G6
A7: S95102 | B7: CGCAATGT | D7: ACATTGCG | F7: S97102 | G7: AAGTCGAG | I7: 870 | J7: =A7&"-"&F7 | K7: =D7&""&G7
A8: S95103 | B8: ACACCTCA | D8: TGAGGTGT | F8: S97103 | G8: CACGTTGT | I8: 871 | J8: =A8&"-"&F8 | K8: =D8&""&G8
A9: S95104 | B9: GAGGCATT | D9: AATGCCTC | F9: S97104 | G9: TCACAGCA | I9: 872 | J9: =A9&"-"&F9 | K9: =D9&""&G9
A10: S95105 | B10: TACTCCAG | D10: CTGGAGTA | F10: S97105 | G10: CTACTTGG | I10: 873 | J10: =A10&"-"&F10 | K10: =D10&""&G10
A11: S95106 | B11: CAGCATAC | D11: GTATGCTG | F11: S97106 | G11: CCTCAGTT | I11: 874 | J11: =A11&"-"&F11 | K11: =D11&""&G11
A12: S95107 | B12: ACTCTCCA | D12: TGGAGAGT | F12: S97107 | G12: TCCTACCT | I12: 875 | J12: =A12&"-"&F12 | K12: =D12&""&G12
A13: S95108 | B13: CTCTATCG | D13: CGATAGAG | F13: S97108 | G13: ATGGCGAA | I13: 876 | J13: =A13&"-"&F13 | K13: =D13&""&G13
... A291: S95384 | B291: TGATAGGC | D291: GCCTATCA | F291: S97384 | G291: CGACCATT | I291: 1152 | J291: =A291&"-"&F291 | K291: =D291&""&G291

Sheet Tagseq
B1: i5 | D1: i5 rc | G1: i7 | J1: Primer | K1: ID | L1: Sequence
A2: AD500 | B2: NNNNNNNN | D2: NNNNNNNN | F2: AD001 | G2: ATCACGTT | J2: AD001 | K2: =A2&"-"&F2 | L2: =D2&""&G2
A3: AD500 | B3: NNNNNNNN | D3: NNNNNNNN | F3: AD002 | G3: CGATGTTT | J3: AD002 | K3: =A3&"-"&F3 | L3: =D3&""&G3
A4: AD500 | B4: NNNNNNNN | D4: NNNNNNNN | F4: AD003 | G4: TTAGGCAT | J4: AD003 | K4: =A4&"-"&F4 | L4: =D4&""&G4
A5: AD500 | B5: NNNNNNNN | D5: NNNNNNNN | F5: AD004 | G5: TGACCACT | J5: AD004 | K5: =A5&"-"&F5 | L5: =D5&""&G5
A6: AD500 | B6: NNNNNNNN | D6: NNNNNNNN | F6: AD005 | G6: ACAGTGGT | J6: AD005 | K6: =A6&"-"&F6 | L6: =D6&""&G6
A7: AD500 | B7: NNNNNNNN | D7: NNNNNNNN | F7: AD006 | G7: GCCAATGT | J7: AD006 | K7: =A7&"-"&F7 | L7: =D7&""&G7
A8: AD500 | B8: NNNNNNNN | D8: NNNNNNNN | F8: AD007 | G8: CAGATCTG | J8: AD007 | K8: =A8&"-"&F8 | L8: =D8&""&G8
A9: AD500 | B9: NNNNNNNN | D9: NNNNNNNN | F9: AD008 | G9: ACTTGATG | J9: AD008 | K9: =A9&"-"&F9 | L9: =D9&""&G9
A10: AD500 | B10: NNNNNNNN | D10: NNNNNNNN | F10: AD009 | G10: GATCAGCG | J10: AD009 | K10: =A10&"-"&F10 | L10: =D10&""&G10
A11: AD500 | B11: NNNNNNNN | D11: NNNNNNNN | F11: AD010 | G11: TAGCTTGT | J11: AD010 | K11: =A11&"-"&F11 | L11: =D11&""&G11
A12: AD500 | B12: NNNNNNNN | D12: NNNNNNNN | F12: AD011 | G12: GGCTACAG | J12: AD011 | K12: =A12&"-"&F12 | L12: =D12&""&G12
A13: AD500 | B13: NNNNNNNN | D13: NNNNNNNN | F13: AD012 | G13: CTTGTACT | J13: AD012 | K13: =A13&"-"&F13 | L13: =D13&""&G13
... A49: AD500 | B49: NNNNNNNN | D49: NNNNNNNN | F49: AD048 | G49: TTCAGCTC | J49: AD048 | K49: =A49&"-"&F49 | L49: =D49&""&G49

Sheet Methylation
B1: i5 | D1: i5 rc | G1: i7 | L1: Primer | M1: ID | N1: Sequence
A2: M501 | B2: ATGTGAAG | D2: CTTCACAT | F2: M701 | G2: CAACACAG | L2: M001 | M2: =A2&"-"&F2 | N2: =D2&""&G2 | P2: M13 | S2: M001
A3: M502 | B3: TTTGGGTG | D3: CACCCAAA | F3: M702 | G3: ACACCTCA | L3: M002 | M3: =A3&"-"&F3 | N3: =D3&""&G3 | P3: M14 | S3: M001
A4: M503 | B4: CACTTCGA | D4: TCGAAGTG | F4: M703 | G4: ACCATAGG | L4: M003 | M4: =A4&"-"&F4 | N4: =D4&""&G4 | P4: M49 | S4: M001
A5: M504 | B5: AGAGTCAA | D5: TTGACTCT | F5: M704 | G5: CAGGTAAG | L5: M004 | M5: =A5&"-"&F5 | N5: =D5&""&G5 | P5: M51 | S5: M001
A6: M505 | B6: AACCGAGA | D6: TCTCGGTT | F6: M705 | G6: AACGCACA | L6: M005 | M6: =A6&"-"&F6 | N6: =D6&""&G6 | P6: M60 | S6: M001
A7: M506 | B7: AACGTGAT | D7: ATCACGTT | F7: M706 | G7: TAGTCTCG | L7: M006 | M7: =A7&"-"&F7 | N7: =D7&""&G7 | P7: M95 | S7: M001
A8: M507 | B8: AGTTGGCT | D8: AGCCAACT | F8: M707 | G8: CAGTCACA | L8: M007 | M8: =A8&"-"&F8 | N8: =D8&""&G8 | S8: M001
A9: M508 | B9: CAATGTGG | D9: CCACATTG | F9: M708 | G9: CCAACACT | L9: M008 | M9: =A9&"-"&F9 | N9: =D9&""&G9 | S9: M001
A10: M509 | B10: GAGCTCAA | D10: TTGAGCTC | F10: M709 | G10: ACATGCCA | L10: M009 | M10: =A10&"-"&F10 | N10: =D10&""&G10 | S10: M001
A11: M510 | B11: AACGGTCA | D11: TGACCGTT | F11: M710 | G11: ATTCCGCT | L11: M010 | M11: =A11&"-"&F11 | N11: =D11&""&G11
A12: M511 | B12: ATGGTTGC | D12: GCAACCAT | F12: M711 | G12: CAAGGTAC | L12: M011 | M12: =A12&"-"&F12 | N12: =D12&""&G12
A13: M512 | B13: ATAAGGCG | D13: CGCCTTAT | F13: M712 | G13: CCATGAAC | L13: M012 | M13: =A13&"-"&F13 | N13: =D13&""&G13
A14: M513 | B14: GAAGCAAG | D14: CTTGCTTC | F14: M713 | G14: TCAGCCTT | L14: M013 | M14: =A14&"-"&F14 | N14: =D14&""&G14
A15: M514 | B15: CTTGTCGG | D15: CCGACAAG | F15: M714 | G15: CAGTGCTT | L15: M014 | M15: =A15&"-"&F15 | N15: =D15&""&G15
A16: M515 | B16: CTCGAGTG | D16: CACTCGAG | F16: M715 | G16: CTCGAACA | L16: M015 | M16: =A16&"-"&F16 | N16: =D16&""&G16
A17: M516 | B17: CCGTACAG | D17: CTGTACGG | F17: M716 | G17: ACAGTTCG | L17: M016 | M17: =A17&"-"&F17 | N17: =D17&""&G17
A18: M517 | B18: CATTCATG | D18: CATGAATG | F18: M717 | G18: ATCCTTCC | L18: M017 | M18: =A18&"-"&F18 | N18: =D18&""&G18
A19: M518 | B19: CATGATAG | D19: CTATCATG | F19: M718 | G19: CGAAGTCA | L19: M018 | M19: =A19&"-"&F19 | N19: =D19&""&G19
A20: M519 | B20: ATCGGTGG | D20: CCACCGAT | F20: M719 | G20: CTCTATCG | L20: M019 | M20: =A20&"-"&F20 | N20: =D20&""&G20
A21: M520 | B21: ATACTAGG | D21: CCTAGTAT | F21: M720 | G21: ACTCTCCA | L21: M020 | M21: =A21&"-"&F21 | N21: =D21&""&G21
A22: M521 | B22: AGGTCTTG | D22: CAAGACCT | F22: M721 | G22: TCCTCATG | L22: M021 | M22: =A22&"-"&F22 | N22: =D22&""&G22
... A193: M5192 | B193: ACGATCAG | D193: CTGATCGT | F193: M7192 | G193: ATATGCGC | L193: M192 | M193: =A193&"-"&F193 | N193: =D193&""&G193

Sheet AC PRIMER
B1: I5 | D1: I5RC | G1: I7
A2: AC501 | B2: AGGCTATA | D2: TATAGCCT | F2: AC701 | G2: CAACACAG | I2: AC001 | J2: =A2&"-"&F2 | K2: =D2&""&G2
A3: AC502 | B3: AGGCTATA | D3: TATAGCCT | F3: AC702 | G3: ACACCTCA | I3: AC002 | J3: =A3&"-"&F3 | K3: =D3&""&G3
A4: AC503 | B4: AGGCTATA | D4: TATAGCCT | F4: AC703 | G4: ACCATAGG | I4: AC003 | J4: =A4&"-"&F4 | K4: =D4&""&G4
A5: AC504 | B5: AGGCTATA | D5: TATAGCCT | F5: AC704 | G5: CAGGTAAG | I5: AC004 | J5: =A5&"-"&F5 | K5: =D5&""&G5
A6: AC505 | B6: AGGCTATA | D6: TATAGCCT | F6: AC705 | G6: AACGCACA | I6: AC005 | J6: =A6&"-"&F6 | K6: =D6&""&G6
A7: AC506 | B7: AGGCTATA | D7: TATAGCCT | F7: AC706 | G7: TAGTCTCG | I7: AC006 | J7: =A7&"-"&F7 | K7: =D7&""&G7
A8: AC507 | B8: AGGCTATA | D8: TATAGCCT | F8: AC707 | G8: CAGTCACA | I8: AC007 | J8: =A8&"-"&F8 | K8: =D8&""&G8
A9: AC508 | B9: AGGCTATA | D9: TATAGCCT | F9: AC708 | G9: CCAACACT | I9: AC008 | J9: =A9&"-"&F9 | K9: =D9&""&G9
A10: AC509 | B10: AGGCTATA | D10: TATAGCCT | F10: AC709 | G10: ACATGCCA | I10: AC009 | J10: =A10&"-"&F10 | K10: =D10&""&G10
A11: AC510 | B11: AGGCTATA | D11: TATAGCCT | F11: AC710 | G11: ATTCCGCT | I11: AC010 | J11: =A11&"-"&F11 | K11: =D11&""&G11
A12: AC511 | B12: AGGCTATA | D12: TATAGCCT | F12: AC711 | G12: CAAGGTAC | I12: AC011 | J12: =A12&"-"&F12 | K12: =D12&""&G12
A13: AC512 | B13: AGGCTATA | D13: TATAGCCT | F13: AC712 | G13: CCATGAAC | I13: AC012 | J13: =A13&"-"&F13 | K13: =D13&""&G13
... A97: AC596 | B97: GTCAGTAC | D97: GTACTGAC | F97: AC796 | G97: CCATGAAC | I97: AC096 | J97: =A97&"-"&F97 | K97: =D97&""&G97

Sheet Genelove
B1: i5 | D1: i5 RC | G1: i7 | I1: Primer | J1: ID | K1: Sequence
A2: i585 | B2: AGGATAGC | D2: GCTATCCT | F2: i785 | G2: CACCTGTT | I2: R1 | J2: =A2&"-"&F2 | K2: =D2&""&G2 | M2: i589-i792 | R2: i785 | S2: CACCTGTT | V2: i585 | W2: AGGATAGC
A3: i585 | B3: AGGATAGC | D3: GCTATCCT | F3: i786 | G3: CTTCGACT | I3: R2 | J3: =A3&"-"&F3 | K3: =D3&""&G3 | M3: i590-i789 | R3: i786 | S3: CTTCGACT | V3: i586 | W3: GATCTTGC
A4: i585 | B4: AGGATAGC | D4: GCTATCCT | F4: i787 | G4: TGCTTCCA | I4: R3 | J4: =A4&"-"&F4 | K4: =D4&""&G4 | M4: i590-i790 | R4: i787 | S4: TGCTTCCA | V4: i587 | W4: CGATCGAT
A5: i585 | B5: AGGATAGC | D5: GCTATCCT | F5: i788 | G5: AGAACGAG | I5: R4 | J5: =A5&"-"&F5 | K5: =D5&""&G5 | M5: i590-i791 | R5: i788 | S5: AGAACGAG | V5: i588 | W5: ATTAGCCG
A6: i586 | B6: GATCTTGC | D6: GCAAGATC | F6: i785 | G6: CACCTGTT | I6: R5 | J6: =A6&"-"&F6 | K6: =D6&""&G6 | M6: i590-i792 | R6: i789 | S6: GTTCTCGT | V6: i589 | W6: TGTTCCGT
A7: i586 | B7: GATCTTGC | D7: GCAAGATC | F7: i786 | G7: CTTCGACT | I7: R6 | J7: =A7&"-"&F7 | K7: =D7&""&G7 | M7: i591-i789 | R7: i790 | S7: TCAGGCTT | V7: i590 | W7: ATCATGCG
A8: i586 | B8: GATCTTGC | D8: GCAAGATC | F8: i787 | G8: TGCTTCCA | I8: R7 | J8: =A8&"-"&F8 | K8: =D8&""&G8 | M8: i591-i790 | R8: i791 | S8: CCTTGTAG | V8: i591 | W8: CCTTGGAA
A9: i586 | B9: GATCTTGC | D9: GCAAGATC | F9: i788 | G9: AGAACGAG | I9: R8 | J9: =A9&"-"&F9 | K9: =D9&""&G9 | M9: i591-i791 | R9: i792 | S9: GAACATCG | V9: i592 | W9: TCGACAAG
A10: i587 | B10: CGATCGAT | D10: ATCGATCG | F10: i785 | G10: CACCTGTT | I10: R9 | J10: =A10&"-"&F10 | K10: =D10&""&G10 | M10: i591-i792 | R10: i793 | S10: TAACCGGT | V10: i593 | W10: ATCGTCTC
A11: i587 | B11: CGATCGAT | D11: ATCGATCG | F11: i786 | G11: CTTCGACT | I11: R10 | J11: =A11&"-"&F11 | K11: =D11&""&G11 | M11: i592-i789 | R11: i794 | S11: AACCGTTC | V11: i594 | W11: CTAGCTCA
A12: i587 | B12: CGATCGAT | D12: ATCGATCG | F12: i787 | G12: TGCTTCCA | I12: R11 | J12: =A12&"-"&F12 | K12: =D12&""&G12 | M12: i592-i790 | R12: i795 | S12: TGGTACAG | V12: i595 | W12: TCGAGAGT
A13: i587 | B13: CGATCGAT | D13: ATCGATCG | F13: i788 | G13: AGAACGAG | I13: R12 | J13: =A13&"-"&F13 | K13: =D13&""&G13 | M13: i592-i791 | R13: i796 | S13: ATATGCGC | V13: i596 | W13: ACGATCAG
A14: i588 | B14: ATTAGCCG | D14: CGGCTAAT | F14: i785 | G14: CACCTGTT | I14: R13 | J14: =A14&"-"&F14 | K14: =D14&""&G14 | M14: i592-i792
A15: i588 | B15: ATTAGCCG | D15: CGGCTAAT | F15: i786 | G15: CTTCGACT | I15: R14 | J15: =A15&"-"&F15 | K15: =D15&""&G15 | M15: i593-i789
A16: i588 | B16: ATTAGCCG | D16: CGGCTAAT | F16: i787 | G16: TGCTTCCA | I16: R15 | J16: =A16&"-"&F16 | K16: =D16&""&G16 | M16: i593-i790
A17: i588 | B17: ATTAGCCG | D17: CGGCTAAT | F17: i788 | G17: AGAACGAG | I17: R16 | J17: =A17&"-"&F17 | K17: =D17&""&G17 | M17: i593-i791
A18: i589 | B18: TGTTCCGT | D18: ACGGAACA | F18: i785 | G18: CACCTGTT | I18: R17 | J18: =A18&"-"&F18 | K18: =D18&""&G18 | M18: i593-i792
A19: i589 | B19: TGTTCCGT | D19: ACGGAACA | F19: i786 | G19: CTTCGACT | I19: R18 | J19: =A19&"-"&F19 | K19: =D19&""&G19 | M19: i594-i789
A20: i589 | B20: TGTTCCGT | D20: ACGGAACA | F20: i787 | G20: TGCTTCCA | I20: R19 | J20: =A20&"-"&F20 | K20: =D20&""&G20 | M20: i594-i790
A21: i589 | B21: TGTTCCGT | D21: ACGGAACA | F21: i788 | G21: AGAACGAG | I21: R20 | J21: =A21&"-"&F21 | K21: =D21&""&G21 | M21: i594-i791
A22: i590 | B22: ATCATGCG | D22: CGCATGAT | F22: i785 | G22: CACCTGTT | I22: R21 | J22: =A22&"-"&F22 | K22: =D22&""&G22 | M22: i594-i792
A23: i590 | B23: ATCATGCG | D23: CGCATGAT | F23: i786 | G23: CTTCGACT | I23: R22 | J23: =A23&"-"&F23 | K23: =D23&""&G23 | M23: i595-i789
A24: i590 | B24: ATCATGCG | D24: CGCATGAT | F24: i787 | G24: TGCTTCCA | I24: R23 | J24: =A24&"-"&F24 | K24: =D24&""&G24 | M24: i595-i790
A25: i590 | B25: ATCATGCG | D25: CGCATGAT | F25: i788 | G25: AGAACGAG | I25: R24 | J25: =A25&"-"&F25 | K25: =D25&""&G25 | M25: i595-i791
A26: i591 | B26: CCTTGGAA | D26: TTCCAAGG | F26: i785 | G26: CACCTGTT | I26: R25 | J26: =A26&"-"&F26 | K26: =D26&""&G26
A27: i591 | B27: CCTTGGAA | D27: TTCCAAGG | F27: i786 | G27: CTTCGACT | I27: R26 | J27: =A27&"-"&F27 | K27: =D27&""&G27
A28: i591 | B28: CCTTGGAA | D28: TTCCAAGG | F28: i787 | G28: TGCTTCCA | I28: R27 | J28: =A28&"-"&F28 | K28: =D28&""&G28
A29: i591 | B29: CCTTGGAA | D29: TTCCAAGG | F29: i788 | G29: AGAACGAG | I29: R28 | J29: =A29&"-"&F29 | K29: =D29&""&G29
A30: i592 | B30: TCGACAAG | D30: CTTGTCGA | F30: i785 | G30: CACCTGTT | I30: R29 | J30: =A30&"-"&F30 | K30: =D30&""&G30
A31: i592 | B31: TCGACAAG | D31: CTTGTCGA | F31: i786 | G31: CTTCGACT | I31: R30 | J31: =A31&"-"&F31 | K31: =D31&""&G31
A32: i592 | B32: TCGACAAG | D32: CTTGTCGA | F32: i787 | G32: TGCTTCCA | I32: R31 | J32: =A32&"-"&F32 | K32: =D32&""&G32
A33: i592 | B33: TCGACAAG | D33: CTTGTCGA | F33: i788 | G33: AGAACGAG | I33: R32 | J33: =A33&"-"&F33 | K33: =D33&""&G33
A34: i593 | B34: ATCGTCTC | D34: GAGACGAT | F34: i785 | G34: CACCTGTT | I34: R33 | J34: =A34&"-"&F34 | K34: =D34&""&G34
A35: i593 | B35: ATCGTCTC | D35: GAGACGAT | F35: i786 | G35: CTTCGACT | I35: R34 | J35: =A35&"-"&F35 | K35: =D35&""&G35
A36: i593 | B36: ATCGTCTC | D36: GAGACGAT | F36: i787 | G36: TGCTTCCA | I36: R35 | J36: =A36&"-"&F36 | K36: =D36&""&G36
A37: i593 | B37: ATCGTCTC | D37: GAGACGAT | F37: i788 | G37: AGAACGAG | I37: R36 | J37: =A37&"-"&F37 | K37: =D37&""&G37
... A145: i596 | B145: ACGATCAG | D145: CTGATCGT | F145: i796 | G145: ATATGCGC | I145: R144 | J145: =A145&"-"&F145 | K145: =D145&""&G145

Sheet Microbiome
C1: i5rc | E1: i7
A2: N01 | B2: S502 | C2: CTCTCTAT | D2: N701 | E2: TAAGGCGA | G2: N01 | H2: =B2&"-"&D2 | I2: =C2&""&E2 | K2: =Microbiome!I2
A3: N02 | B3: S502 | C3: CTCTCTAT | D3: N702 | E3: CGTACTAG | G3: N02 | H3: =B3&"-"&D3 | I3: =C3&""&E3
A4: N03 | B4: S502 | C4: CTCTCTAT | D4: N703 | E4: AGGCAGAA | G4: N03 | H4: =B4&"-"&D4 | I4: =C4&""&E4
A5: N04 | B5: S502 | C5: CTCTCTAT | D5: N704 | E5: TCCTGAGC | G5: N04 | H5: =B5&"-"&D5 | I5: =C5&""&E5
A6: N05 | B6: S502 | C6: CTCTCTAT | D6: N705 | E6: GGACTCCT | G6: N05 | H6: =B6&"-"&D6 | I6: =C6&""&E6
A7: N06 | B7: S502 | C7: CTCTCTAT | D7: N706 | E7: TAGGCATG | G7: N06 | H7: =B7&"-"&D7 | I7: =C7&""&E7
A8: N07 | B8: S502 | C8: CTCTCTAT | D8: N707 | E8: CTCTCTAC | G8: N07 | H8: =B8&"-"&D8 | I8: =C8&""&E8
A9: N08 | B9: S502 | C9: CTCTCTAT | D9: N710 | E9: CGAGGCTG | G9: N08 | H9: =B9&"-"&D9 | I9: =C9&""&E9
A10: N09 | B10: S502 | C10: CTCTCTAT | D10: N711 | E10: AAGAGGCA | G10: N09 | H10: =B10&"-"&D10 | I10: =C10&""&E10
A11: N10 | B11: S502 | C11: CTCTCTAT | D11: N712 | E11: GTAGAGGA | G11: N10 | H11: =B11&"-"&D11 | I11: =C11&""&E11
A12: N11 | B12: S502 | C12: CTCTCTAT | D12: N714 | E12: GCTCATGA | G12: N11 | H12: =B12&"-"&D12 | I12: =C12&""&E12
A13: N12 | B13: S502 | C13: CTCTCTAT | D13: N715 | E13: ATCTCAGG | G13: N12 | H13: =B13&"-"&D13 | I13: =C13&""&E13
A14: N13 | B14: S503 | C14: TATCCTCT | D14: N701 | E14: TAAGGCGA | G14: N13 | H14: =B14&"-"&D14 | I14: =C14&""&E14
... A97: N96 | B97: S511 | C97: TCTCTCCG | D97: N715 | E97: ATCTCAGG | G97: N96 | H97: =B97&"-"&D97 | I97: =C97&""&E97

Sheet Pico Gold
B1: i5 | D1: i5 RC | G1: i7
A2: U501 | B2: CTAGCGCT | D2: AGCGCTAG | F2: U701 | G2: CCGCGGTT | J2: U1 | K2: =A2&"-"&F2 | L2: =D2&""&G2
A3: U502 | B3: TCGATATC | D3: GATATCGA | F3: U702 | G3: TTATAACC | J3: U2 | K3: =A3&"-"&F3 | L3: =D3&""&G3
A4: U503 | B4: CGTCTGCG | D4: CGCAGACG | F4: U703 | G4: GGACTTGG | J4: U3 | K4: =A4&"-"&F4 | L4: =D4&""&G4
A5: U504 | B5: TACTCATA | D5: TATGAGTA | F5: U704 | G5: AAGTCCAA | J5: U4 | K5: =A5&"-"&F5 | L5: =D5&""&G5
A6: U505 | B6: ACGCACCT | D6: AGGTGCGT | F6: U705 | G6: ATCCACTG | J6: U5 | K6: =A6&"-"&F6 | L6: =D6&""&G6
A7: U506 | B7: GTATGTTC | D7: GAACATAC | F7: U706 | G7: GCTTGTCA | J7: U6 | K7: =A7&"-"&F7 | L7: =D7&""&G7
A8: U507 | B8: CGCTATGT | D8: ACATAGCG | F8: U707 | G8: CAAGCTAG | J8: U7 | K8: =A8&"-"&F8 | L8: =D8&""&G8
A9: U508 | B9: TATCGCAC | D9: GTGCGATA | F9: U708 | G9: TGGATCGA | J9: U8 | K9: =A9&"-"&F9 | L9: =D9&""&G9
A10: U509 | B10: TCTGTTGG | D10: CCAACAGA | F10: U709 | G10: AGTTCAGG | J10: U9 | K10: =A10&"-"&F10 | L10: =D10&""&G10
A11: U510 | B11: CTCACCAA | D11: TTGGTGAG | F11: U710 | G11: GACCTGAA | J11: U10 | K11: =A11&"-"&F11 | L11: =D11&""&G11
A12: U511 | B12: GAACCGCG | D12: CGCGGTTC | F12: U711 | G12: TCTCTACT | J12: U11 | K12: =A12&"-"&F12 | L12: =D12&""&G12
A13: U512 | B13: AGGTTATA | D13: TATAACCT | F13: U712 | G13: CTCTCGTC | J13: U12 | K13: =A13&"-"&F13 | L13: =D13&""&G13
... A97: U596 | B97: GTCTACAC | D97: GTGTAGAC | F97: U796 | G97: CTAGCGCT | J97: U96 | K97: =A97&"-"&F97 | L97: =D97&""&G97

Sheet TWIST
B1: i5 tu mgi | D1: i5 tu illumina | H1: i7 tu mgi | K1: i7 tu illumina | M1: Primer | N1: id | O1: seq i5mgii7illu | P1: seq i5illu7illu | Q1: seqi5mgii7mgi | R1: seq i5illui7mgi
A2: TA501 | B2: AATATTCG | D2: CGAATATT | G2: TA701 | H2: TCTTCAGC | K2: GCTGAAGA | M2: T0001 | N2: =A2&"-"&G2 | O2: =B2&""&K2 | P2: =D2&""&K2 | Q2: =B2&""&H2 | R2: =D2&""&H2
A3: TB501 | B3: CAGACAAC | D3: GTTGTCTG | G3: TB701 | H3: CACGGATA | K3: TATCCGTG | M3: T0002 | N3: =A3&"-"&G3 | O3: =B3&""&K3 | P3: =D3&""&K3 | Q3: =B3&""&H3 | R3: =D3&""&H3
A4: TC501 | B4: GGAGCAGA | D4: TCTGCTCC | G4: TC701 | H4: TTGATAGA | K4: TCTATCAA | M4: T0003 | N4: =A4&"-"&G4 | O4: =B4&""&K4 | P4: =D4&""&K4 | Q4: =B4&""&H4 | R4: =D4&""&H4
A5: TD501 | B5: GTCCGTAG | D5: CTACGGAC | G5: TD701 | H5: TCCTGCCT | K5: AGGCAGGA | M5: T0004 | N5: =A5&"-"&G5 | O5: =B5&""&K5 | P5: =D5&""&K5 | Q5: =B5&""&H5 | R5: =D5&""&H5
A6: TE501 | B6: GTTCACGT | D6: ACGTGAAC | G6: TE701 | H6: GATAGTCG | K6: CGACTATC | M6: T0005 | N6: =A6&"-"&G6 | O6: =B6&""&K6 | P6: =D6&""&K6 | Q6: =B6&""&H6 | R6: =D6&""&H6
A7: TF501 | B7: CGATGGTT | D7: AACCATCG | G7: TF701 | H7: AGATCGAA | K7: TTCGATCT | M7: T0006 | N7: =A7&"-"&G7 | O7: =B7&""&K7 | P7: =D7&""&K7 | Q7: =B7&""&H7 | R7: =D7&""&H7
A8: TG501 | B8: TCCGTGCA | D8: TGCACGGA | G8: TG701 | H8: GCTCCTTC | K8: GAAGGAGC | M8: T0007 | N8: =A8&"-"&G8 | O8: =B8&""&K8 | P8: =D8&""&K8 | Q8: =B8&""&H8 | R8: =D8&""&H8
A9: TH501 | B9: GCGCAGAG | D9: CTCTGCGC | G9: TH701 | H9: ACGGATAG | K9: CTATCCGT | M9: T0008 | N9: =A9&"-"&G9 | O9: =B9&""&K9 | P9: =D9&""&K9 | Q9: =B9&""&H9 | R9: =D9&""&H9
A10: TA502 | B10: GACTTAGT | D10: ACTAAGTC | G10: TA702 | H10: TAGCCTCA | K10: TGAGGCTA | M10: T0009 | N10: =A10&"-"&G10 | O10: =B10&""&K10 | P10: =D10&""&K10 | Q10: =B10&""&H10 | R10: =D10&""&H10
A11: TB502 | B11: CTGCATCG | D11: CGATGCAG | G11: TB702 | H11: GCAATCGG | K11: CCGATTGC | M11: T0010 | N11: =A11&"-"&G11 | O11: =B11&""&K11 | P11: =D11&""&K11 | Q11: =B11&""&H11 | R11: =D11&""&H11
A12: TC502 | B12: AAGTGCCA | D12: TGGCACTT | G12: TC702 | H12: TGAGTTAT | K12: ATAACTCA | M12: T0011 | N12: =A12&"-"&G12 | O12: =B12&""&K12 | P12: =D12&""&K12 | Q12: =B12&""&H12 | R12: =D12&""&H12
A13: TD502 | B13: ATTCAACC | D13: GGTTGAAT | G13: TD702 | H13: CGTCCAGA | K13: TCTGGACG | M13: T0012 | N13: =A13&"-"&G13 | O13: =B13&""&K13 | P13: =D13&""&K13 | Q13: =B13&""&H13 | R13: =D13&""&H13
... A97: TH512 | B97: ACATAGTC | D97: GACTATGT | G97: TH712 | H97: AATCGTCT | K97: AGACGATT | M97: T0096 | N97: =A97&"-"&G97 | O97: =B97&""&K97 | P97: =D97&""&K97 | Q97: =B97&""&H97 | R97: =D97&""&H97

Sheet PRIMER LOCKED
A1: PRIMER | B1: ID | C1: SEQ | G1: NAME
A2: 1 | B2: D501-D701 | C2: TATAGCCTATTACTCG | G2: 1234
A3: 2 | B3: D501-D702 | C3: TATAGCCTTCCGGAGA | G3: 1234
A4: 3 | B4: D501-D703 | C4: TATAGCCTCGCTCATT | G4: 1234
A5: 4 | B5: D501-D704 | C5: TATAGCCTGAGATTCC | G5: 1234
A6: 5 | B6: D502-D701 | C6: ATAGAGGCATTACTCG | G6: 1234
A7: 6 | B7: D502-D702 | C7: ATAGAGGCTCCGGAGA | G7: 1234
A8: 7 | B8: D502-D703 | C8: ATAGAGGCCGCTCATT | G8: 1234
A9: 8 | B9: D502-D704 | C9: ATAGAGGCGAGATTCC | G9: 1234
A10: 9 | B10: D503-D701 | C10: CCTATCCTATTACTCG | G10: 1234
A11: 10 | B11: D503-D702 | C11: CCTATCCTTCCGGAGA | G11: 1234
A12: 11 | B12: D503-D703 | C12: CCTATCCTCGCTCATT | G12: 1234
A13: 12 | B13: D503-D704 | C13: CCTATCCTGAGATTCC | G13: 1234
... A1153: 1152 | B1153: S95384-S97384 | C1153: GCCTATCACGACCATT | G1153: 101112
A1154: AD001 | B1154: AD500-AD001 | C1154: NNNNNNNNATCACGTT | G1154: Tag
A1155: AD002 | B1155: AD500-AD002 | C1155: NNNNNNNNCGATGTTT | G1155: Tag
A1156: AD003 | B1156: AD500-AD003 | C1156: NNNNNNNNTTAGGCAT | G1156: Tag
A1157: AD004 | B1157: AD500-AD004 | C1157: NNNNNNNNTGACCACT | G1157: Tag
A1158: AD005 | B1158: AD500-AD005 | C1158: NNNNNNNNACAGTGGT | G1158: Tag
A1159: AD006 | B1159: AD500-AD006 | C1159: NNNNNNNNGCCAATGT | G1159: Tag
A1160: AD007 | B1160: AD500-AD007 | C1160: NNNNNNNNCAGATCTG | G1160: Tag
A1161: AD008 | B1161: AD500-AD008 | C1161: NNNNNNNNACTTGATG | G1161: Tag
A1162: AD009 | B1162: AD500-AD009 | C1162: NNNNNNNNGATCAGCG | G1162: Tag
A1163: AD010 | B1163: AD500-AD010 | C1163: NNNNNNNNTAGCTTGT | G1163: Tag
A1164: AD011 | B1164: AD500-AD011 | C1164: NNNNNNNNGGCTACAG | G1164: Tag
A1165: AD012 | B1165: AD500-AD012 | C1165: NNNNNNNNCTTGTACT | G1165: Tag
... A2113: LC096 | B2113: LC508-LC712 | C2113: GTACTGACCTATCGCT | G2113: AMOY

Sheet Sheet1
A1: U502-U702 | B1: GATATCGATTATAACC
A2: U503-U703 | B2: CGCAGACGGGACTTGG
A3: U504-U704 | B3: TATGAGTAAAGTCCAA
A4: U505-U705 | B4: AGGTGCGTATCCACTG
A5: U506-U706 | B5: GAACATACGCTTGTCA
A6: U507-U707 | B6: ACATAGCGCAAGCTAG
A7: U508-U708 | B7: GTGCGATATGGATCGA
A8: U509-U709 | B8: CCAACAGAAGTTCAGG
A9: U510-U710 | B9: TTGGTGAGGACCTGAA
A10: U511-U711 | B10: CGCGGTTCTCTCTACT
A11: U512-U712 | B11: TATAACCTCTCTCGTC
A12: U513-U713 | B12: AAGGATGACCAAGTCT
... A23: U524-U724 | B23: GTTAATTGATGAGGCC

Sheet MỒI T7
A1: MỒI TỪ META | B1: ID | C1: SEQ | G1: TÁCH CỘT | K1: I7 | O1: TỪ FILE MỒI
B2: =VLOOKUP(A2,'PRIMER LOCKED'!$A$2:$C$3000,2,FALSE) | C2: =VLOOKUP(B2,'PRIMER LOCKED'!$B$2:$D$3000,2,FALSE)
B3: =VLOOKUP(A3,'PRIMER LOCKED'!$A$2:$C$3000,2,FALSE) | C3: =VLOOKUP(B3,'PRIMER LOCKED'!$B$2:$D$3000,2,FALSE)
B4: =VLOOKUP(A4,'PRIMER LOCKED'!$A$2:$C$3000,2,FALSE) | C4: =VLOOKUP(B4,'PRIMER LOCKED'!$B$2:$D$3000,2,FALSE)
B5: =VLOOKUP(A5,'PRIMER LOCKED'!$A$2:$C$3000,2,FALSE) | C5: =VLOOKUP(B5,'PRIMER LOCKED'!$B$2:$D$3000,2,FALSE)
B6: =VLOOKUP(A6,'PRIMER LOCKED'!$A$2:$C$3000,2,FALSE) | C6: =VLOOKUP(B6,'PRIMER LOCKED'!$B$2:$D$3000,2,FALSE)
B7: =VLOOKUP(A7,'PRIMER LOCKED'!$A$2:$C$3000,2,FALSE) | C7: =VLOOKUP(B7,'PRIMER LOCKED'!$B$2:$D$3000,2,FALSE)
B8: =VLOOKUP(A8,'PRIMER LOCKED'!$A$2:$C$3000,2,FALSE) | C8: =VLOOKUP(B8,'PRIMER LOCKED'!$B$2:$D$3000,2,FALSE)
B9: =VLOOKUP(A9,'PRIMER LOCKED'!$A$2:$C$3000,2,FALSE) | C9: =VLOOKUP(B9,'PRIMER LOCKED'!$B$2:$D$3000,2,FALSE)
B10: =VLOOKUP(A10,'PRIMER LOCKED'!$A$2:$C$3000,2,FALSE) | C10: =VLOOKUP(B10,'PRIMER LOCKED'!$B$2:$D$3000,2,FALSE)
B11: =VLOOKUP(A11,'PRIMER LOCKED'!$A$2:$C$3000,2,FALSE) | C11: =VLOOKUP(B11,'PRIMER LOCKED'!$B$2:$D$3000,2,FALSE)
B12: =VLOOKUP(A12,'PRIMER LOCKED'!$A$2:$C$3000,2,FALSE) | C12: =VLOOKUP(B12,'PRIMER LOCKED'!$B$2:$D$3000,2,FALSE)
B13: =VLOOKUP(A13,'PRIMER LOCKED'!$A$2:$C$3000,2,FALSE) | C13: =VLOOKUP(B13,'PRIMER LOCKED'!$B$2:$D$3000,2,FALSE)
... B318: =VLOOKUP(A318,'PRIMER LOCKED'!$A$2:$C$3000,2,FALSE) | C318: =VLOOKUP(B318,'PRIMER LOCKED'!$B$2:$D$3000,2,FALSE)
B319: ULTRASHEAR | C319: HRDCNV
B320: =VLOOKUP(A320,'PRIMER LOCKED'!$A$2:$C$3000,2,FALSE) | C320: =VLOOKUP(B320,'PRIMER LOCKED'!$B$2:$D$3000,2,FALSE)
B321: =VLOOKUP(A321,'PRIMER LOCKED'!$A$2:$C$3000,2,FALSE) | C321: =VLOOKUP(B321,'PRIMER LOCKED'!$B$2:$D$3000,2,FALSE)
B322: =VLOOKUP(A322,'PRIMER LOCKED'!$A$2:$C$3000,2,FALSE) | C322: =VLOOKUP(B322,'PRIMER LOCKED'!$B$2:$D$3000,2,FALSE)
B323: =VLOOKUP(A323,'PRIMER LOCKED'!$A$2:$C$3000,2,FALSE) | C323: =VLOOKUP(B323,'PRIMER LOCKED'!$B$2:$D$3000,2,FALSE)
B324: =VLOOKUP(A324,'PRIMER LOCKED'!$A$2:$C$3000,2,FALSE) | C324: =VLOOKUP(B324,'PRIMER LOCKED'!$B$2:$D$3000,2,FALSE)
B325: =VLOOKUP(A325,'PRIMER LOCKED'!$A$2:$C$3000,2,FALSE) | C325: =VLOOKUP(B325,'PRIMER LOCKED'!$B$2:$D$3000,2,FALSE)
B326: =VLOOKUP(A326,'PRIMER LOCKED'!$A$2:$C$3000,2,FALSE) | C326: =VLOOKUP(B326,'PRIMER LOCKED'!$B$2:$D$3000,2,FALSE)
B327: =VLOOKUP(A327,'PRIMER LOCKED'!$A$2:$C$3000,2,FALSE) | C327: =VLOOKUP(B327,'PRIMER LOCKED'!$B$2:$D$3000,2,FALSE)
B328: =VLOOKUP(A328,'PRIMER LOCKED'!$A$2:$C$3000,2,FALSE) | C328: =VLOOKUP(B328,'PRIMER LOCKED'!$B$2:$D$3000,2,FALSE)
B329: =VLOOKUP(A329,'PRIMER LOCKED'!$A$2:$C$3000,2,FALSE) | C329: =VLOOKUP(B329,'PRIMER LOCKED'!$B$2:$D$3000,2,FALSE)
B330: =VLOOKUP(A330,'PRIMER LOCKED'!$A$2:$C$3000,2,FALSE) | C330: =VLOOKUP(B330,'PRIMER LOCKED'!$B$2:$D$3000,2,FALSE)
B331: =VLOOKUP(A331,'PRIMER LOCKED'!$A$2:$C$3000,2,FALSE) | C331: =VLOOKUP(B331,'PRIMER LOCKED'!$B$2:$D$3000,2,FALSE)
... B335: =VLOOKUP(A335,'PRIMER LOCKED'!$A$2:$C$3000,2,FALSE) | C335: =VLOOKUP(B335,'PRIMER LOCKED'!$B$2:$D$3000,2,FALSE)
B336: ONCO13REP3 | C336: =VLOOKUP(B336,'PRIMER LOCKED'!$B$2:$D$3000,2,FALSE)
B337: ONCO13REP3 | C337: =VLOOKUP(B337,'PRIMER LOCKED'!$B$2:$D$3000,2,FALSE)
B338: ONCO13REP3 | C338: =VLOOKUP(B338,'PRIMER LOCKED'!$B$2:$D$3000,2,FALSE)
B339: ONCO13REP3 | C339: =VLOOKUP(B339,'PRIMER LOCKED'!$B$2:$D$3000,2,FALSE)
B340: CNVGW | C340: =VLOOKUP(B340,'PRIMER LOCKED'!$B$2:$D$3000,2,FALSE)
B341: CNVGW | C341: =VLOOKUP(B341,'PRIMER LOCKED'!$B$2:$D$3000,2,FALSE)
B342: CNVGW | C342: =VLOOKUP(B342,'PRIMER LOCKED'!$B$2:$D$3000,2,FALSE)
B343: CNVGW | C343: =VLOOKUP(B343,'PRIMER LOCKED'!$B$2:$D$3000,2,FALSE)
B344: =VLOOKUP(A344,'PRIMER LOCKED'!$A$2:$C$3000,2,FALSE) | C344: =VLOOKUP(B344,'PRIMER LOCKED'!$B$2:$D$3000,2,FALSE)
B345: =VLOOKUP(A345,'PRIMER LOCKED'!$A$2:$C$3000,2,FALSE) | C345: =VLOOKUP(B345,'PRIMER LOCKED'!$B$2:$D$3000,2,FALSE)
B346: =VLOOKUP(A346,'PRIMER LOCKED'!$A$2:$C$3000,2,FALSE) | C346: =VLOOKUP(B346,'PRIMER LOCKED'!$B$2:$D$3000,2,FALSE)
B347: =VLOOKUP(A347,'PRIMER LOCKED'!$A$2:$C$3000,2,FALSE) | C347: =VLOOKUP(B347,'PRIMER LOCKED'!$B$2:$D$3000,2,FALSE)
...

Sheet Nanodigm
A1: I5_Index_ID | B1: index2 | D1: I5 RC· | F1: I7_Index_ID | G1: index
A2: ND501 | B2: TGCTTATC | D2: GATAAGCA | F2: ND701 | G2: GTGTCCTC | J2: ND01 | K2: =A2&"-"&F2 | L2: =D2&""&G2 | Y2: ND01 | Z2: ND701 | AA2: ND501
A3: ND502 | B3: CCTAATAG | D3: CTATTAGG | F3: ND702 | G3: CCTCAGGA | J3: ND02 | K3: =A3&"-"&F3 | L3: =D3&""&G3 | Y3: ND02 | Z3: ND702 | AA3: ND502
A4: ND503 | B4: GTACGCCA | D4: TGGCGTAC | F4: ND703 | G4: TACGTACT | J4: ND03 | K4: =A4&"-"&F4 | L4: =D4&""&G4 | Y4: ND03 | Z4: ND703 | AA4: ND503
A5: ND504 | B5: AAGGCGGT | D5: ACCGCCTT | F5: ND704 | G5: AGAAGTAG | J5: ND04 | K5: =A5&"-"&F5 | L5: =D5&""&G5 | Y5: ND04 | Z5: ND704 | AA5: ND504
A6: ND505 | B6: AATCGGCA | D6: TGCCGATT | F6: ND705 | G6: AGGAGTCA | J6: ND05 | K6: =A6&"-"&F6 | L6: =D6&""&G6 | Y6: ND05 | Z6: ND705 | AA6: ND505
A7: ND506 | B7: GCCACCTG | D7: CAGGTGGC | F7: ND706 | G7: TTCCAGAT | J7: ND06 | K7: =A7&"-"&F7 | L7: =D7&""&G7 | Y7: ND06 | Z7: ND706 | AA7: ND506
A8: ND507 | B8: CGAGTAAC | D8: GTTACTCG | F8: ND707 | G8: CCATCAGG | J8: ND07 | K8: =A8&"-"&F8 | L8: =D8&""&G8 | Y8: ND07 | Z8: ND707 | AA8: ND507
A9: ND508 | B9: TTGTATGT | D9: ACATACAA | F9: ND708 | G9: GATGTCTC | J9: ND08 | K9: =A9&"-"&F9 | L9: =D9&""&G9 | Y9: ND08 | Z9: ND708 | AA9: ND508
A10: ND509 | B10: TCCACAGT | D10: ACTGTGGA | F10: ND709 | G10: CAAGCCTA | J10: ND09 | K10: =A10&"-"&F10 | L10: =D10&""&G10 | Y10: ND09 | Z10: ND709 | AA10: ND509
A11: ND510 | B11: CGTTATTA | D11: TAATAACG | F11: ND710 | G11: GCTCGTGT | J11: ND10 | K11: =A11&"-"&F11 | L11: =D11&""&G11 | Y11: ND10 | Z11: ND710 | AA11: ND510
A12: ND511 | B12: ATAGTGCC | D12: GGCACTAT | F12: ND711 | G12: ATGTAGAG | J12: ND11 | K12: =A12&"-"&F12 | L12: =D12&""&G12 | Y12: ND11 | Z12: ND711 | AA12: ND511
A13: ND512 | B13: GAGCGCAG | D13: CTGCGCTC | F13: ND712 | G13: TGCATACC | J13: ND12 | K13: =A13&"-"&F13 | L13: =D13&""&G13 | Y13: ND12 | Z13: ND712 | AA13: ND512
... A97: ND596 | B97: TACCGACC | D97: GGTCGGTA | F97: ND796 | G97: GACGCGTT | J97: ND96 | K97: =A97&"-"&F97 | L97: =D97&""&G97 | Y97: ND96 | Z97: ND796 | AA97: ND596
A99: ND501 | B99: TGCTTATC
A100: ND502 | B100: CCTAATAG
A101: ND503 | B101: GTACGCCA
A102: ND504 | B102: AAGGCGGT
A103: ND505 | B103: AATCGGCA
A104: ND506 | B104: GCCACCTG
A105: ND507 | B105: CGAGTAAC
A106: ND508 | B106: TTGTATGT
A107: ND509 | B107: TCCACAGT
A108: ND510 | B108: CGTTATTA
A109: ND511 | B109: ATAGTGCC
A110: ND512 | B110: GAGCGCAG
... A194: ND596 | B194: TACCGACC

Sheet MỒI MGI

Sheet template barcode
A1: #barcodeName | B1: T72_C_R8772_MGI_25_12
A2: #misMatch1 | B2: 0
A3: #misMatch2 | B3: 0
B4: =VLOOKUP(A2,'PRIMER LOCKED'!$A$2:$C$3000,2,FALSE) | C4: =VLOOKUP(B2,'PRIMER LOCKED'!$B$2:$D$3000,2,FALSE)
B5: =VLOOKUP(A3,'PRIMER LOCKED'!$A$2:$C$3000,2,FALSE) | C5: =VLOOKUP(B3,'PRIMER LOCKED'!$B$2:$D$3000,2,FALSE)
B6: =VLOOKUP(A4,'PRIMER LOCKED'!$A$2:$C$3000,2,FALSE) | C6: =VLOOKUP(B4,'PRIMER LOCKED'!$B$2:$D$3000,2,FALSE)
B7: =VLOOKUP(A5,'PRIMER LOCKED'!$A$2:$C$3000,2,FALSE) | C7: =VLOOKUP(B5,'PRIMER LOCKED'!$B$2:$D$3000,2,FALSE)
B8: =VLOOKUP(A6,'PRIMER LOCKED'!$A$2:$C$3000,2,FALSE) | C8: =VLOOKUP(B6,'PRIMER LOCKED'!$B$2:$D$3000,2,FALSE)
B9: =VLOOKUP(A7,'PRIMER LOCKED'!$A$2:$C$3000,2,FALSE) | C9: =VLOOKUP(B7,'PRIMER LOCKED'!$B$2:$D$3000,2,FALSE)
B10: =VLOOKUP(A8,'PRIMER LOCKED'!$A$2:$C$3000,2,FALSE) | C10: =VLOOKUP(B8,'PRIMER LOCKED'!$B$2:$D$3000,2,FALSE)
B11: =VLOOKUP(A9,'PRIMER LOCKED'!$A$2:$C$3000,2,FALSE) | C11: =VLOOKUP(B9,'PRIMER LOCKED'!$B$2:$D$3000,2,FALSE)
B12: =VLOOKUP(A10,'PRIMER LOCKED'!$A$2:$C$3000,2,FALSE) | C12: =VLOOKUP(B10,'PRIMER LOCKED'!$B$2:$D$3000,2,FALSE)
B13: =VLOOKUP(A11,'PRIMER LOCKED'!$A$2:$C$3000,2,FALSE) | C13: =VLOOKUP(B11,'PRIMER LOCKED'!$B$2:$D$3000,2,FALSE)
B14: =VLOOKUP(A12,'PRIMER LOCKED'!$A$2:$C$3000,2,FALSE) | C14: =VLOOKUP(B12,'PRIMER LOCKED'!$B$2:$D$3000,2,FALSE)
B15: =VLOOKUP(A13,'PRIMER LOCKED'!$A$2:$C$3000,2,FALSE) | C15: =VLOOKUP(B13,'PRIMER LOCKED'!$B$2:$D$3000,2,FALSE)
... B320: =VLOOKUP(A318,'PRIMER LOCKED'!$A$2:$C$3000,2,FALSE) | C320: =VLOOKUP(B318,'PRIMER LOCKED'!$B$2:$D$3000,2,FALSE)
B321: ULTRASHEAR | C321: HRDCNV
B322: =VLOOKUP(A320,'PRIMER LOCKED'!$A$2:$C$3000,2,FALSE) | C322: =VLOOKUP(B320,'PRIMER LOCKED'!$B$2:$D$3000,2,FALSE)
B323: =VLOOKUP(A321,'PRIMER LOCKED'!$A$2:$C$3000,2,FALSE) | C323: =VLOOKUP(B321,'PRIMER LOCKED'!$B$2:$D$3000,2,FALSE)
B324: =VLOOKUP(A322,'PRIMER LOCKED'!$A$2:$C$3000,2,FALSE) | C324: =VLOOKUP(B322,'PRIMER LOCKED'!$B$2:$D$3000,2,FALSE)
B325: =VLOOKUP(A323,'PRIMER LOCKED'!$A$2:$C$3000,2,FALSE) | C325: =VLOOKUP(B323,'PRIMER LOCKED'!$B$2:$D$3000,2,FALSE)
B326: =VLOOKUP(A324,'PRIMER LOCKED'!$A$2:$C$3000,2,FALSE) | C326: =VLOOKUP(B324,'PRIMER LOCKED'!$B$2:$D$3000,2,FALSE)
B327: =VLOOKUP(A325,'PRIMER LOCKED'!$A$2:$C$3000,2,FALSE) | C327: =VLOOKUP(B325,'PRIMER LOCKED'!$B$2:$D$3000,2,FALSE)
B328: =VLOOKUP(A326,'PRIMER LOCKED'!$A$2:$C$3000,2,FALSE) | C328: =VLOOKUP(B326,'PRIMER LOCKED'!$B$2:$D$3000,2,FALSE)
B329: =VLOOKUP(A327,'PRIMER LOCKED'!$A$2:$C$3000,2,FALSE) | C329: =VLOOKUP(B327,'PRIMER LOCKED'!$B$2:$D$3000,2,FALSE)
B330: =VLOOKUP(A328,'PRIMER LOCKED'!$A$2:$C$3000,2,FALSE) | C330: =VLOOKUP(B328,'PRIMER LOCKED'!$B$2:$D$3000,2,FALSE)
B331: =VLOOKUP(A329,'PRIMER LOCKED'!$A$2:$C$3000,2,FALSE) | C331: =VLOOKUP(B329,'PRIMER LOCKED'!$B$2:$D$3000,2,FALSE)
B332: =VLOOKUP(A330,'PRIMER LOCKED'!$A$2:$C$3000,2,FALSE) | C332: =VLOOKUP(B330,'PRIMER LOCKED'!$B$2:$D$3000,2,FALSE)
B333: =VLOOKUP(A331,'PRIMER LOCKED'!$A$2:$C$3000,2,FALSE) | C333: =VLOOKUP(B331,'PRIMER LOCKED'!$B$2:$D$3000,2,FALSE)
... B337: =VLOOKUP(A335,'PRIMER LOCKED'!$A$2:$C$3000,2,FALSE) | C337: =VLOOKUP(B335,'PRIMER LOCKED'!$B$2:$D$3000,2,FALSE)
B338: ONCO13REP3 | C338: =VLOOKUP(B336,'PRIMER LOCKED'!$B$2:$D$3000,2,FALSE)
B339: ONCO13REP3 | C339: =VLOOKUP(B337,'PRIMER LOCKED'!$B$2:$D$3000,2,FALSE)
B340: ONCO13REP3 | C340: =VLOOKUP(B338,'PRIMER LOCKED'!$B$2:$D$3000,2,FALSE)
B341: ONCO13REP3 | C341: =VLOOKUP(B339,'PRIMER LOCKED'!$B$2:$D$3000,2,FALSE)
B342: CNVGW | C342: =VLOOKUP(B340,'PRIMER LOCKED'!$B$2:$D$3000,2,FALSE)
B343: CNVGW | C343: =VLOOKUP(B341,'PRIMER LOCKED'!$B$2:$D$3000,2,FALSE)
B344: CNVGW | C344: =VLOOKUP(B342,'PRIMER LOCKED'!$B$2:$D$3000,2,FALSE)
B345: CNVGW | C345: =VLOOKUP(B343,'PRIMER LOCKED'!$B$2:$D$3000,2,FALSE)
B346: =VLOOKUP(A344,'PRIMER LOCKED'!$A$2:$C$3000,2,FALSE) | C346: =VLOOKUP(B344,'PRIMER LOCKED'!$B$2:$D$3000,2,FALSE)
B347: =VLOOKUP(A345,'PRIMER LOCKED'!$A$2:$C$3000,2,FALSE) | C347: =VLOOKUP(B345,'PRIMER LOCKED'!$B$2:$D$3000,2,FALSE)
...

Sheet AMOY
B1: I5 | C1: I5RC
A2: LC501 | B2: AGGCTATA | C2: TATAGCCT | I2: LC701 | J2: CGAGTAAT | O2: LC001 | P2: =A2&"-"&I2 | Q2: =C2&""&J2 | T2: LC701 | U2: LC501
A3: LC502 | B3: GCCTCTAT | C3: ATAGAGGC | I3: LC701 | J3: CGAGTAAT | O3: LC002 | P3: =A3&"-"&I3 | Q3: =C3&""&J3 | T3: LC701 | U3: LC502
A4: LC503 | B4: AGGATAGG | C4: CCTATCCT | I4: LC701 | J4: CGAGTAAT | O4: LC003 | P4: =A4&"-"&I4 | Q4: =C4&""&J4 | T4: LC701 | U4: LC503
A5: LC504 | B5: TCAGAGCC | C5: GGCTCTGA | I5: LC701 | J5: CGAGTAAT | O5: LC004 | P5: =A5&"-"&I5 | Q5: =C5&""&J5 | T5: LC701 | U5: LC504
A6: LC505 | B6: CTTCGCCT | C6: AGGCGAAG | I6: LC701 | J6: CGAGTAAT | O6: LC005 | P6: =A6&"-"&I6 | Q6: =C6&""&J6 | T6: LC701 | U6: LC505
A7: LC506 | B7: TAAGATTA | C7: TAATCTTA | I7: LC701 | J7: CGAGTAAT | O7: LC006 | P7: =A7&"-"&I7 | Q7: =C7&""&J7 | T7: LC701 | U7: LC506
A8: LC507 | B8: ACGTCCTG | C8: CAGGACGT | I8: LC701 | J8: CGAGTAAT | O8: LC007 | P8: =A8&"-"&I8 | Q8: =C8&""&J8 | T8: LC701 | U8: LC507
A9: LC508 | B9: GTCAGTAC | C9: GTACTGAC | I9: LC701 | J9: CGAGTAAT | O9: LC008 | P9: =A9&"-"&I9 | Q9: =C9&""&J9 | T9: LC701 | U9: LC508
A10: LC501 | B10: AGGCTATA | C10: TATAGCCT | I10: LC702 | J10: TCTCCGGA | O10: LC009 | P10: =A10&"-"&I10 | Q10: =C10&""&J10 | T10: LC702 | U10: LC501
A11: LC502 | B11: GCCTCTAT | C11: ATAGAGGC | I11: LC702 | J11: TCTCCGGA | O11: LC010 | P11: =A11&"-"&I11 | Q11: =C11&""&J11 | T11: LC702 | U11: LC502
A12: LC503 | B12: AGGATAGG | C12: CCTATCCT | I12: LC702 | J12: TCTCCGGA | O12: LC011 | P12: =A12&"-"&I12 | Q12: =C12&""&J12 | T12: LC702 | U12: LC503
A13: LC504 | B13: TCAGAGCC | C13: GGCTCTGA | I13: LC702 | J13: TCTCCGGA | O13: LC012 | P13: =A13&"-"&I13 | Q13: =C13&""&J13 | T13: LC702 | U13: LC504
... A97: LC508 | B97: GTCAGTAC | C97: GTACTGAC | I97: LC712 | J97: CTATCGCT | O97: LC096 | P97: =A97&"-"&I97 | Q97: =C97&""&J97 | T97: LC712 | U97: LC508
